2024-01-20 11:19:59.303 ERROR (MainThread) [root] Uncaught exception
Traceback (most recent call last):
  File "<frozen runpy>", line 198, in _run_module_as_main
  File "<frozen runpy>", line 88, in _run_code
  File "/usr/src/homeassistant/homeassistant/__main__.py", line 221, in <module>
    sys.exit(main())
             ^^^^^^
  File "/usr/src/homeassistant/homeassistant/__main__.py", line 209, in main
    exit_code = runner.run(runtime_conf)
                ^^^^^^^^^^^^^^^^^^^^^^^^
  File "/usr/src/homeassistant/homeassistant/runner.py", line 188, in run
    return loop.run_until_complete(setup_and_run_hass(runtime_config))
           ^^^^^^^^^^^^^^^^^^^^^^^^^^^^^^^^^^^^^^^^^^^^^^^^^^^^^^^^^^^
  File "/usr/local/lib/python3.11/asyncio/base_events.py", line 653, in run_until_complete
    return future.result()
           ^^^^^^^^^^^^^^^
  File "/usr/src/homeassistant/homeassistant/runner.py", line 154, in setup_and_run_hass
    hass = await bootstrap.async_setup_hass(runtime_config)
           ^^^^^^^^^^^^^^^^^^^^^^^^^^^^^^^^^^^^^^^^^^^^^^^^
  File "/usr/src/homeassistant/homeassistant/bootstrap.py", line 147, in async_setup_hass
    config_dict = await conf_util.async_hass_config_yaml(hass)
                  ^^^^^^^^^^^^^^^^^^^^^^^^^^^^^^^^^^^^^^^^^^^^
  File "/usr/src/homeassistant/homeassistant/config.py", line 501, in async_hass_config_yaml
    await merge_packages_config(hass, config, core_config.get(CONF_PACKAGES, {}))
  File "/usr/src/homeassistant/homeassistant/config.py", line 1029, in merge_packages_config
    PACKAGES_CONFIG_SCHEMA(packages)
  File "/usr/src/homeassistant/homeassistant/helpers/config_validation.py", line 588, in verify
    return cast(dict, schema(value))
                      ^^^^^^^^^^^^^
  File "/usr/local/lib/python3.11/site-packages/voluptuous/schema_builder.py", line 272, in __call__
    return self._compiled([], data)
           ^^^^^^^^^^^^^^^^^^^^^^^^
  File "/usr/local/lib/python3.11/site-packages/voluptuous/schema_builder.py", line 595, in validate_dict
    return base_validate(path, iteritems(data), out)
           ^^^^^^^^^^^^^^^^^^^^^^^^^^^^^^^^^^^^^^^^^
  File "/usr/local/lib/python3.11/site-packages/voluptuous/schema_builder.py", line 433, in validate_mapping
    raise er.MultipleInvalid(errors)
voluptuous.error.MultipleInvalid: expected a dictionary for dictionary value @ data['panel_iframe']
